Workbook

Sheet Designs
A1: Sno | B1: design_name | C1: design_code | D1: published | E1: active | F1: Selling price | G1: Light | H1: Cabinets | I1: 3 shelf backpanel | J1: Square | K1: Rectangle | L1: Shelf | N1: Final Price | O1: L Profile color | P1: Trim | Q1: Sqaure | R1: Rectangle | S1: Shelf | T1: Cost | U1: Selling price after discount | V1: Transport cost | W1: CP cost | X1: Margin
A2: 1 | B2: BR-1-1 | C2: BR-1-1 | D2: No | E2: Yes | F2: =VLOOKUP(C2, 'Pivot Table 2'!$A$1:$B$123, 2, FALSE) -> 5000 | G2: 0 | H2: 0 | I2: 0 | J2: 0 | N2: =F2+G2*4*1000+H2*10000+1*1500*I2+1*J2*1000+1*K2*1000+1*L2*1000 -> 5000 | T2: =VLOOKUP(C2, 'Pivot Table 2'!$A$1:$C$119, 3, FALSE) -> 2736 | U2: =(1-AA$6)*F2 -> 3000 | V2: =$AA$7 -> 500 | W2: =$AA$8 -> 4500 | X2: =U2-T2-V2-W2 -> -4736
A3: 2 | B3: BR-1-2 | C3: BR-1-2 | D3: No | E3: Yes | F3: =VLOOKUP(C3, 'Pivot Table 2'!$A$1:$B$123, 2, FALSE) -> 5000 | G3: 0 | H3: 0 | I3: 0 | J3: 0 | N3: =F3+G3*4*1000+H3*10000+1*1500*I3+1*J3*1000+1*K3*1000+1*L3*1000 -> 5000 | T3: =VLOOKUP(C3, 'Pivot Table 2'!$A$1:$C$119, 3, FALSE) -> 2736 | U3: =(1-AA$6)*F3 -> 3000 | V3: =$AA$7 -> 500 | W3: =$AA$8 -> 4500 | X3: =U3-T3-V3-W3 -> -4736
A4: 3 | B4: BR-2-1 | C4: BR-2-1 | D4: No | E4: Yes | F4: =VLOOKUP(C4, 'Pivot Table 2'!$A$1:$B$123, 2, FALSE) -> 5000 | G4: 0 | H4: 0 | I4: 0 | J4: 0 | N4: =F4+G4*4*1000+H4*10000+1*1500*I4+1*J4*1000+1*K4*1000+1*L4*1000 -> 5000 | T4: =VLOOKUP(C4, 'Pivot Table 2'!$A$1:$C$119, 3, FALSE) -> 2736 | U4: =(1-AA$6)*F4 -> 3000 | V4: =$AA$7 -> 500 | W4: =$AA$8 -> 4500 | X4: =U4-T4-V4-W4 -> -4736
A5: 4 | B5: BR-2-2 | C5: BR-2-2 | D5: No | E5: Yes | F5: =VLOOKUP(C5, 'Pivot Table 2'!$A$1:$B$123, 2, FALSE) -> 5000 | G5: 0 | H5: 0 | I5: 0 | J5: 0 | N5: =F5+G5*4*1000+H5*10000+1*1500*I5+1*J5*1000+1*K5*1000+1*L5*1000 -> 5000 | T5: =VLOOKUP(C5, 'Pivot Table 2'!$A$1:$C$119, 3, FALSE) -> 2736 | U5: =(1-AA$6)*F5 -> 3000 | V5: =$AA$7 -> 500 | W5: =$AA$8 -> 4500 | X5: =U5-T5-V5-W5 -> -4736
A6: 5 | B6: Noctis Haven (BR-3-1) | C6: BR-3-1 | D6: Yes | E6: Yes | F6: =VLOOKUP(C6, 'Pivot Table 2'!$A$1:$B$123, 2, FALSE) -> 26500 | G6: 0 | H6: 0 | I6: 0 | J6: 0 | K6: 0 | L6: 0 | M6: NA | N6: =F6+G6*4*1000+H6*10000+1*1500*I6+1*J6*1000+1*K6*1000+1*L6*1000 -> 26500 | O6: WHSWBIW08S223 | P6: No | Q6: 0 | R6: 0 | S6: 0 | T6: =VLOOKUP(C6, 'Pivot Table 2'!$A$1:$C$119, 3, FALSE) -> 13826.339 | U6: =(1-AA$6)*F6 -> 15900 | V6: =$AA$7 -> 500 | W6: =$AA$8 -> 4500 | X6: =U6-T6-V6-W6 -> -2926.339 | Y6: =25% -> 0.25 | Z6: Discount | AA6: =40% -> 0.4
A7: 6 | B7: Caelum Nest (BR-3-2) | C7: BR-3-2 | D7: Yes | E7: Yes | F7: =VLOOKUP(C7, 'Pivot Table 2'!$A$1:$B$123, 2, FALSE) -> 24000 | G7: 0 | H7: 0 | I7: 0 | J7: 0 | K7: 0 | L7: 0 | M7: NA | N7: =F7+G7*4*1000+H7*10000+1*1500*I7+1*J7*1000+1*K7*1000+1*L7*1000 -> 24000 | O7: WHSWBIW01S216 | P7: No | Q7: 0 | R7: 0 | S7: 0 | T7: =VLOOKUP(C7, 'Pivot Table 2'!$A$1:$C$119, 3, FALSE) -> 12503.966 | U7: =(1-AA$6)*F7 -> 14400 | V7: =$AA$7 -> 500 | W7: =$AA$8 -> 4500 | X7: =U7-T7-V7-W7 -> -3103.9661 | Y7: =25% -> 0.25 | Z7: Transport | AA7: =500 -> 500
A8: 7 | B8: Amber Silence (BR-4-1) | C8: BR-4-1 | D8: Yes | E8: Yes | F8: =VLOOKUP(C8, 'Pivot Table 2'!$A$1:$B$123, 2, FALSE) -> 34500 | G8: 0 | H8: 0 | I8: 0 | J8: 2 | K8: 1 | L8: 0 | M8: Light | N8: =F8+G8*4*1000+H8*10000+1*1500*I8+1*J8*1000+1*K8*1000+1*L8*1000 -> 37500 | O8: WHSWBIW01S216 | P8: No | Q8: WHSWSSBWBLWS171 | R8: WHSWSRBWBLWS181 | S8: 0 | T8: =VLOOKUP(C8, 'Pivot Table 2'!$A$1:$C$119, 3, FALSE) -> 17164.644 | U8: =(1-AA$6)*F8 -> 20700 | V8: =$AA$7 -> 500 | W8: =$AA$8 -> 4500 | X8: =U8-T8-V8-W8 -> -1464.6441 | Y8: =35% -> 0.35 | Z8: CP cost | AA8: =4500 -> 4500 | AB8: =AA8/(9.5*10) -> 47.368421
A9: 8 | B9: Elaris Woodline (BR-4-2) | C9: BR-4-2 | D9: Yes | E9: Yes | F9: =VLOOKUP(C9, 'Pivot Table 2'!$A$1:$B$123, 2, FALSE) -> 39500 | G9: 0 | H9: 0 | I9: 0 | J9: 2 | K9: 1 | L9: 0 | M9: Light | N9: =F9+G9*4*1000+H9*10000+1*1500*I9+1*J9*1000+1*K9*1000+1*L9*1000 -> 42500 | O9: WHSWBIW03S218 | P9: No | Q9: WHSWSSBWBLWS171 | R9: WHSWSRBWBLWS181 | S9: 0 | T9: =VLOOKUP(C9, 'Pivot Table 2'!$A$1:$C$119, 3, FALSE) -> 20893.458 | U9: =(1-AA$6)*F9 -> 23700 | V9: =$AA$7 -> 500 | W9: =$AA$8 -> 4500 | X9: =U9-T9-V9-W9 -> -2193.4576 | Y9: =35% -> 0.35
A10: 9 | B10: BR-5-1 | C10: BR-5-1 | D10: No | E10: Yes | F10: =VLOOKUP(C10, 'Pivot Table 2'!$A$1:$B$123, 2, FALSE) -> 35000 | G10: 0 | H10: 0 | I10: 0 | J10: 0 | N10: =F10+G10*4*1000+H10*10000+1*1500*I10+1*J10*1000+1*K10*1000+1*L10*1000 -> 35000 | T10: =VLOOKUP(C10, 'Pivot Table 2'!$A$1:$C$119, 3, FALSE) -> 17636.339 | U10: =(1-AA$6)*F10 -> 21000 | V10: =$AA$7 -> 500 | W10: =$AA$8 -> 4500 | X10: =U10-T10-V10-W10 -> -1636.339
A11: 10 | B11: BR-5-2 | C11: BR-5-2 | D11: No | E11: Yes | F11: =VLOOKUP(C11, 'Pivot Table 2'!$A$1:$B$123, 2, FALSE) -> 35000 | G11: 0 | H11: 0 | I11: 0 | J11: 0 | N11: =F11+G11*4*1000+H11*10000+1*1500*I11+1*J11*1000+1*K11*1000+1*L11*1000 -> 35000 | T11: =VLOOKUP(C11, 'Pivot Table 2'!$A$1:$C$119, 3, FALSE) -> 14653.288 | U11: =(1-AA$6)*F11 -> 21000 | V11: =$AA$7 -> 500 | W11: =$AA$8 -> 4500 | X11: =U11-T11-V11-W11 -> 1346.7119
A12: 11 | B12: Solstice Haven (BR-6-1) | C12: BR-6-1 | D12: Yes | E12: Yes | F12: =VLOOKUP(C12, 'Pivot Table 2'!$A$1:$B$123, 2, FALSE) -> 63000 | G12: 0 | H12: 0 | I12: 0 | J12: 4 | K12: 0 | L12: 0 | M12: Light | N12: =F12+G12*4*1000+H12*10000+1*1500*I12+1*J12*1000+1*K12*1000+1*L12*1000 -> 67000 | O12: WHSWBIW02S217 | P12: ?? | Q12: WHSWSSBWBLWS171 | R12: 0 | S12: 0 | T12: =VLOOKUP(C12, 'Pivot Table 2'!$A$1:$C$119, 3, FALSE) -> 29897.864 | U12: =(1-AA$6)*F12 -> 37800 | V12: =$AA$7 -> 500 | W12: =$AA$8 -> 4500 | X12: =U12-T12-V12-W12 -> 2902.1356 | Y12: =40% -> 0.4
A13: 12 | B13: Morvane Essence (BR-6-2) | C13: BR-6-2 | D13: Yes | E13: Yes | F13: =VLOOKUP(C13, 'Pivot Table 2'!$A$1:$B$123, 2, FALSE) -> 53000 | G13: 0 | H13: 0 | I13: 0 | J13: 4 | K13: 0 | L13: 0 | M13: Light | N13: =F13+G13*4*1000+H13*10000+1*1500*I13+1*J13*1000+1*K13*1000+1*L13*1000 -> 57000 | O13: WHSWBIW01S216 | P13: No | Q13: WHSWSSBWBLWS171 | R13: 0 | S13: 0 | T13: =VLOOKUP(C13, 'Pivot Table 2'!$A$1:$C$119, 3, FALSE) -> 25695.831 | U13: =(1-AA$6)*F13 -> 31800 | V13: =$AA$7 -> 500 | W13: =$AA$8 -> 4500 | X13: =U13-T13-V13-W13 -> 1104.1695 | Y13: =40% -> 0.4
A14: 13 | B14: BR-7-1 | C14: BR-7-1 | D14: No | E14: Yes | F14: =VLOOKUP(C14, 'Pivot Table 2'!$A$1:$B$123, 2, FALSE) -> 35000 | G14: 0 | H14: 0 | I14: 0 | J14: 0 | N14: =F14+G14*4*1000+H14*10000+1*1500*I14+1*J14*1000+1*K14*1000+1*L14*1000 -> 35000 | T14: =VLOOKUP(C14, 'Pivot Table 2'!$A$1:$C$119, 3, FALSE) -> 14925.831 | U14: =(1-AA$6)*F14 -> 21000 | V14: =$AA$7 -> 500 | W14: =$AA$8 -> 4500 | X14: =U14-T14-V14-W14 -> 1074.1695
A15: 14 | B15: BR-7-2 | C15: BR-7-2 | D15: No | E15: Yes | F15: =VLOOKUP(C15, 'Pivot Table 2'!$A$1:$B$123, 2, FALSE) -> 35000 | G15: 0 | H15: 0 | I15: 0 | J15: 0 | N15: =F15+G15*4*1000+H15*10000+1*1500*I15+1*J15*1000+1*K15*1000+1*L15*1000 -> 35000 | T15: =VLOOKUP(C15, 'Pivot Table 2'!$A$1:$C$119, 3, FALSE) -> 16144.814 | U15: =(1-AA$6)*F15 -> 21000 | V15: =$AA$7 -> 500 | W15: =$AA$8 -> 4500 | X15: =U15-T15-V15-W15 -> -144.81356
A16: 15 | B16: Mirevan Grove (BR-8-1) | C16: BR-8-1 | D16: Yes | E16: Yes | F16: =VLOOKUP(C16, 'Pivot Table 2'!$A$1:$B$123, 2, FALSE) -> 50000 | G16: 0 | H16: 0 | I16: 0 | J16: 4 | K16: 0 | L16: 0 | M16: Mid | N16: =F16+G16*4*1000+H16*10000+1*1500*I16+1*J16*1000+1*K16*1000+1*L16*1000 -> 54000 | O16: WHSWBIW03S218 | P16: No | Q16: WHSWSSBWBMWS172 | R16: 0 | S16: 0 | T16: =VLOOKUP(C16, 'Pivot Table 2'!$A$1:$C$119, 3, FALSE) -> 26712.169 | U16: =(1-AA$6)*F16 -> 30000 | V16: =$AA$7 -> 500 | W16: =$AA$8 -> 4500 | X16: =U16-T16-V16-W16 -> -1712.1695 | Y16: =35% -> 0.35
A17: 16 | B17: Alba Caliza (BR-8-2) | C17: BR-8-2 | D17: Yes | E17: Yes | F17: =VLOOKUP(C17, 'Pivot Table 2'!$A$1:$B$123, 2, FALSE) -> 50000 | G17: 0 | H17: 0 | I17: 0 | J17: 4 | K17: 0 | L17: 0 | M17: Mid | N17: =F17+G17*4*1000+H17*10000+1*1500*I17+1*J17*1000+1*K17*1000+1*L17*1000 -> 54000 | O17: WHSWBIW02S217 | P17: Yes | Q17: WHSWSSBWBMWS172 | R17: 0 | S17: 0 | T17: =VLOOKUP(C17, 'Pivot Table 2'!$A$1:$C$119, 3, FALSE) -> 26712.169 | U17: =(1-AA$6)*F17 -> 30000 | V17: =$AA$7 -> 500 | W17: =$AA$8 -> 4500 | X17: =U17-T17-V17-W17 -> -1712.1695 | Y17: =35% -> 0.35
A18: 17 | B18: Velvet Whisperline (BR-12-1) | C18: BR-12-1 | D18: Yes | E18: Yes | F18: =VLOOKUP(C18, 'Pivot Table 2'!$A$1:$B$123, 2, FALSE) -> 41000 | G18: 0 | H18: 0 | I18: 0 | J18: 0 | K18: 2 | L18: 1 | M18: Light | N18: =F18+G18*4*1000+H18*10000+1*1500*I18+1*J18*1000+1*K18*1000+1*L18*1000 -> 44000 | O18: WHSWBIW02S217 | P18: No | Q18: 0 | R18: WHSWSRBWBLWS181 | S18: WHSWS300SLWS191 | T18: =VLOOKUP(C18, 'Pivot Table 2'!$A$1:$C$119, 3, FALSE) -> 20289.898 | U18: =(1-AA$6)*F18 -> 24600 | V18: =$AA$7 -> 500 | W18: =$AA$8 -> 4500 | X18: =U18-T18-V18-W18 -> -689.89831 | Y18: =35% -> 0.35
A19: 18 | B19: BR-13-1 | C19: BR-13-1 | D19: No | E19: Yes | F19: =VLOOKUP(C19, 'Pivot Table 2'!$A$1:$B$123, 2, FALSE) -> 42500 | G19: 0 | H19: 0 | I19: 0 | J19: 0 | N19: =F19+G19*4*1000+H19*10000+1*1500*I19+1*J19*1000+1*K19*1000+1*L19*1000 -> 42500 | T19: =VLOOKUP(C19, 'Pivot Table 2'!$A$1:$C$119, 3, FALSE) -> 19504.475 | U19: =(1-AA$6)*F19 -> 25500 | V19: =$AA$7 -> 500 | W19: =$AA$8 -> 4500 | X19: =U19-T19-V19-W19 -> 995.52542
A20: 19 | B20: Elmara Nest (BR-15-1) | C20: BR-15-1 | D20: Yes | E20: Yes | F20: =VLOOKUP(C20, 'Pivot Table 2'!$A$1:$B$123, 2, FALSE) -> 45800 | G20: 0 | H20: 0 | I20: 0 | J20: 3 | K20: 0 | L20: 2 | M20: Light | N20: =F20+G20*4*1000+H20*10000+1*1500*I20+1*J20*1000+1*K20*1000+1*L20*1000 -> 50800 | O20: WHSWBIW02S217 | P20: Yes | Q20: WHSWSSBWBMWS172 | R20: 0 | S20: WHSWS300SLWS191 | T20: =VLOOKUP(C20, 'Pivot Table 2'!$A$1:$C$119, 3, FALSE) -> 25651.161 | U20: =(1-AA$6)*F20 -> 27480 | V20: =$AA$7 -> 500 | W20: =$AA$8 -> 4500 | X20: =U20-T20-V20-W20 -> -3171.1614 | Y20: =30% -> 0.3
A21: 20 | B21: Velisse Grove (BR-15-2) | C21: BR-15-2 | D21: Yes | E21: Yes | F21: =VLOOKUP(C21, 'Pivot Table 2'!$A$1:$B$123, 2, FALSE) -> 44800 | G21: 0 | H21: 0 | I21: 0 | J21: 3 | K21: 0 | L21: 2 | M21: Light | N21: =F21+G21*4*1000+H21*10000+1*1500*I21+1*J21*1000+1*K21*1000+1*L21*1000 -> 49800 | O21: WHSWBIW02S217 | P21: No | Q21: WHSWSSBWBMWS172 | R21: 0 | S21: WHSWS300SLWS191 | T21: =VLOOKUP(C21, 'Pivot Table 2'!$A$1:$C$119, 3, FALSE) -> 24976.161 | U21: =(1-AA$6)*F21 -> 26880 | V21: =$AA$7 -> 500 | W21: =$AA$8 -> 4500 | X21: =U21-T21-V21-W21 -> -3096.1614 | Y21: =30% -> 0.3
A22: 21 | B22: BR-9-1 | C22: BR-9-1 | D22: No | E22: Yes | F22: =VLOOKUP(C22, 'Pivot Table 2'!$A$1:$B$123, 2, FALSE) -> 95000 | G22: 0 | H22: 0 | I22: 0 | J22: 0 | N22: =F22+G22*4*1000+H22*10000+1*1500*I22+1*J22*1000+1*K22*1000+1*L22*1000 -> 95000 | T22: =VLOOKUP(C22, 'Pivot Table 2'!$A$1:$C$119, 3, FALSE) -> 52516.645 | U22: =(1-AA$6)*F22 -> 57000 | V22: =$AA$7 -> 500 | W22: =$AA$8 -> 4500 | X22: =U22-T22-V22-W22 -> -516.64542
A23: 22 | B23: BR-19-1 | C23: BR-19-1 | D23: No | E23: Yes | F23: =VLOOKUP(C23, 'Pivot Table 2'!$A$1:$B$123, 2, FALSE) -> 5000 | G23: 0 | H23: 0 | I23: 0 | J23: 0 | N23: =F23+G23*4*1000+H23*10000+1*1500*I23+1*J23*1000+1*K23*1000+1*L23*1000 -> 5000 | T23: =VLOOKUP(C23, 'Pivot Table 2'!$A$1:$C$119, 3, FALSE) -> 2736 | U23: =(1-AA$6)*F23 -> 3000 | V23: =$AA$7 -> 500 | W23: =$AA$8 -> 4500 | X23: =U23-T23-V23-W23 -> -4736
A24: 23 | B24: Celestine Veil (BR-10-1) | C24: BR-10-1 | D24: Yes | E24: Yes | F24: =VLOOKUP(C24, 'Pivot Table 2'!$A$1:$B$123, 2, FALSE) -> 5000 | G24: 0 | H24: 0 | I24: 0 | J24: 0 | K24: 0 | L24: 0 | M24: NA | N24: =F24+G24*4*1000+H24*10000+1*1500*I24+1*J24*1000+1*K24*1000+1*L24*1000 -> 5000 | O24: WHSWBIW02S217 | P24: No | Q24: 0 | R24: 0 | S24: 0 | T24: =VLOOKUP(C24, 'Pivot Table 2'!$A$1:$C$119, 3, FALSE) -> 2736 | U24: =(1-AA$6)*F24 -> 3000 | V24: =$AA$7 -> 500 | W24: =$AA$8 -> 4500 | X24: =U24-T24-V24-W24 -> -4736
A25: 24 | B25: Lignora Arch (BR-10-2) | C25: BR-10-2 | D25: Yes | E25: Yes | F25: =VLOOKUP(C25, 'Pivot Table 2'!$A$1:$B$123, 2, FALSE) -> 47500 | G25: 0 | H25: 0 | I25: 0 | J25: 0 | K25: 0 | L25: 0 | M25: NA | N25: =F25+G25*4*1000+H25*10000+1*1500*I25+1*J25*1000+1*K25*1000+1*L25*1000 -> 47500 | O25: WHSWBIW02S217 | P25: No | Q25: 0 | R25: 0 | S25: 0 | T25: =VLOOKUP(C25, 'Pivot Table 2'!$A$1:$C$119, 3, FALSE) -> 27529.548 | U25: =(1-AA$6)*F25 -> 28500 | V25: =$AA$7 -> 500 | W25: =$AA$8 -> 4500 | X25: =U25-T25-V25-W25 -> -4029.5485 | Y25: =30% -> 0.3
A26: 25 | B26: BR-31-1 | C26: BR-31-1 | D26: No | E26: Yes | F26: =VLOOKUP(C26, 'Pivot Table 2'!$A$1:$B$123, 2, FALSE) -> 140000 | G26: 0 | H26: 0 | I26: 0 | J26: 0 | N26: =F26+G26*4*1000+H26*10000+1*1500*I26+1*J26*1000+1*K26*1000+1*L26*1000 -> 140000 | T26: =VLOOKUP(C26, 'Pivot Table 2'!$A$1:$C$119, 3, FALSE) -> 77406.968 | U26: =(1-AA$6)*F26 -> 84000 | V26: =$AA$7 -> 500 | W26: =$AA$8 -> 4500 | X26: =U26-T26-V26-W26 -> 1593.0319
A27: 26 | B27: BR-31-2 | C27: BR-31-2 | D27: No | E27: Yes | F27: =VLOOKUP(C27, 'Pivot Table 2'!$A$1:$B$123, 2, FALSE) -> 140000 | G27: 0 | H27: 0 | I27: 0 | J27: 0 | N27: =F27+G27*4*1000+H27*10000+1*1500*I27+1*J27*1000+1*K27*1000+1*L27*1000 -> 140000 | T27: =VLOOKUP(C27, 'Pivot Table 2'!$A$1:$C$119, 3, FALSE) -> 77406.968 | U27: =(1-AA$6)*F27 -> 84000 | V27: =$AA$7 -> 500 | W27: =$AA$8 -> 4500 | X27: =U27-T27-V27-W27 -> 1593.0319
A28: 27 | B28: BR-20-1 | C28: BR-20-1 | D28: No | E28: Yes | F28: =VLOOKUP(C28, 'Pivot Table 2'!$A$1:$B$123, 2, FALSE) -> 5000 | G28: 0 | H28: 0 | I28: 0 | J28: 0 | N28: =F28+G28*4*1000+H28*10000+1*1500*I28+1*J28*1000+1*K28*1000+1*L28*1000 -> 5000 | T28: =VLOOKUP(C28, 'Pivot Table 2'!$A$1:$C$119, 3, FALSE) -> 2736 | U28: =(1-AA$6)*F28 -> 3000 | V28: =$AA$7 -> 500 | W28: =$AA$8 -> 4500 | X28: =U28-T28-V28-W28 -> -4736
A29: 28 | B29: BR-20-2 | C29: BR-20-2 | D29: No | E29: Yes | F29: =VLOOKUP(C29, 'Pivot Table 2'!$A$1:$B$123, 2, FALSE) -> 5000 | G29: 0 | H29: 0 | I29: 0 | J29: 0 | N29: =F29+G29*4*1000+H29*10000+1*1500*I29+1*J29*1000+1*K29*1000+1*L29*1000 -> 5000 | T29: =VLOOKUP(C29, 'Pivot Table 2'!$A$1:$C$119, 3, FALSE) -> 2736 | U29: =(1-AA$6)*F29 -> 3000 | V29: =$AA$7 -> 500 | W29: =$AA$8 -> 4500 | X29: =U29-T29-V29-W29 -> -4736
A30: 29 | B30: BR-11-1 | C30: BR-11-1 | D30: No | E30: Yes | F30: =VLOOKUP(C30, 'Pivot Table 2'!$A$1:$B$123, 2, FALSE) -> 5000 | G30: 0 | H30: 0 | I30: 0 | J30: 0 | N30: =F30+G30*4*1000+H30*10000+1*1500*I30+1*J30*1000+1*K30*1000+1*L30*1000 -> 5000 | T30: =VLOOKUP(C30, 'Pivot Table 2'!$A$1:$C$119, 3, FALSE) -> 2736 | U30: =(1-AA$6)*F30 -> 3000 | V30: =$AA$7 -> 500 | W30: =$AA$8 -> 4500 | X30: =U30-T30-V30-W30 -> -4736
A31: 30 | B31: BR-11-2 | C31: BR-11-2 | D31: No | E31: Yes | F31: =VLOOKUP(C31, 'Pivot Table 2'!$A$1:$B$123, 2, FALSE) -> 5000 | G31: 0 | H31: 0 | I31: 0 | J31: 0 | N31: =F31+G31*4*1000+H31*10000+1*1500*I31+1*J31*1000+1*K31*1000+1*L31*1000 -> 5000 | T31: =VLOOKUP(C31, 'Pivot Table 2'!$A$1:$C$119, 3, FALSE) -> 2736 | U31: =(1-AA$6)*F31 -> 3000 | V31: =$AA$7 -> 500 | W31: =$AA$8 -> 4500 | X31: =U31-T31-V31-W31 -> -4736
A32: 31 | B32: BR-22-1 | C32: BR-22-1 | D32: No | E32: Yes | F32: =VLOOKUP(C32, 'Pivot Table 2'!$A$1:$B$123, 2, FALSE) -> 5000 | G32: 0 | H32: 0 | I32: 0 | J32: 0 | N32: =F32+G32*4*1000+H32*10000+1*1500*I32+1*J32*1000+1*K32*1000+1*L32*1000 -> 5000 | T32: =VLOOKUP(C32, 'Pivot Table 2'!$A$1:$C$119, 3, FALSE) -> 2736 | U32: =(1-AA$6)*F32 -> 3000 | V32: =$AA$7 -> 500 | W32: =$AA$8 -> 4500 | X32: =U32-T32-V32-W32 -> -4736
A33: 32 | B33: BR-23-1 | C33: BR-23-1 | D33: No | E33: Yes | F33: =VLOOKUP(C33, 'Pivot Table 2'!$A$1:$B$123, 2, FALSE) -> 5000 | G33: 0 | H33: 0 | I33: 0 | J33: 0 | N33: =F33+G33*4*1000+H33*10000+1*1500*I33+1*J33*1000+1*K33*1000+1*L33*1000 -> 5000 | T33: =VLOOKUP(C33, 'Pivot Table 2'!$A$1:$C$119, 3, FALSE) -> 2736 | U33: =(1-AA$6)*F33 -> 3000 | V33: =$AA$7 -> 500 | W33: =$AA$8 -> 4500 | X33: =U33-T33-V33-W33 -> -4736
A34: 33 | B34: BR-23-2 | C34: BR-23-2 | D34: No | E34: Yes | F34: =VLOOKUP(C34, 'Pivot Table 2'!$A$1:$B$123, 2, FALSE) -> 5000 | G34: 0 | H34: 0 | I34: 0 | J34: 0 | N34: =F34+G34*4*1000+H34*10000+1*1500*I34+1*J34*1000+1*K34*1000+1*L34*1000 -> 5000 | T34: =VLOOKUP(C34, 'Pivot Table 2'!$A$1:$C$119, 3, FALSE) -> 2736 | U34: =(1-AA$6)*F34 -> 3000 | V34: =$AA$7 -> 500 | W34: =$AA$8 -> 4500 | X34: =U34-T34-V34-W34 -> -4736
A35: 34 | B35: BR-14-1 | C35: BR-14-1 | D35: No | E35: Yes | F35: =VLOOKUP(C35, 'Pivot Table 2'!$A$1:$B$123, 2, FALSE) -> 5000 | G35: 0 | H35: 0 | I35: 0 | J35: 0 | N35: =F35+G35*4*1000+H35*10000+1*1500*I35+1*J35*1000+1*K35*1000+1*L35*1000 -> 5000 | T35: =VLOOKUP(C35, 'Pivot Table 2'!$A$1:$C$119, 3, FALSE) -> 2736 | U35: =(1-AA$6)*F35 -> 3000 | V35: =$AA$7 -> 500 | W35: =$AA$8 -> 4500 | X35: =U35-T35-V35-W35 -> -4736
A36: 35 | B36: BR-14-2 | C36: BR-14-2 | D36: No | E36: Yes | F36: =VLOOKUP(C36, 'Pivot Table 2'!$A$1:$B$123, 2, FALSE) -> 5000 | G36: 0 | H36: 0 | I36: 0 | J36: 0 | N36: =F36+G36*4*1000+H36*10000+1*1500*I36+1*J36*1000+1*K36*1000+1*L36*1000 -> 5000 | T36: =VLOOKUP(C36, 'Pivot Table 2'!$A$1:$C$119, 3, FALSE) -> 2736 | U36: =(1-AA$6)*F36 -> 3000 | V36: =$AA$7 -> 500 | W36: =$AA$8 -> 4500 | X36: =U36-T36-V36-W36 -> -4736
A37: 36 | B37: BR-28-1 | C37: BR-28-1 | D37: No | E37: Yes | F37: =VLOOKUP(C37, 'Pivot Table 2'!$A$1:$B$123, 2, FALSE) -> 5000 | G37: 0 | H37: 0 | I37: 0 | J37: 0 | N37: =F37+G37*4*1000+H37*10000+1*1500*I37+1*J37*1000+1*K37*1000+1*L37*1000 -> 5000 | T37: =VLOOKUP(C37, 'Pivot Table 2'!$A$1:$C$119, 3, FALSE) -> 2736 | U37: =(1-AA$6)*F37 -> 3000 | V37: =$AA$7 -> 500 | W37: =$AA$8 -> 4500 | X37: =U37-T37-V37-W37 -> -4736
... A56: 55 | B56: BR-33-1 | C56: BR-33-1 | D56: No | E56: Yes | F56: =VLOOKUP(C56, 'Pivot Table 2'!$A$1:$B$123, 2, FALSE) -> 5000 | G56: 0 | H56: 0 | I56: 0 | J56: 0 | N56: =F56+G56*4*1000+H56*10000+1*1500*I56+1*J56*1000+1*K56*1000+1*L56*1000 -> 5000 | T56: =VLOOKUP(C56, 'Pivot Table 2'!$A$1:$C$119, 3, FALSE) -> 2736 | U56: =(1-AA$6)*F56 -> 3000 | V56: =$AA$7 -> 500 | W56: =$AA$8 -> 4500 | X56: =U56-T56-V56-W56 -> -4736
A57: 56 | B57: Scandinavian Warmth (LR-09L-1) | C57: LR-09L-1 | D57: Yes | E57: Yes | F57: =VLOOKUP(C57, 'Pivot Table 2'!$A$1:$B$123, 2, FALSE) -> 40000 | G57: 0 | H57: 0 | I57: 0 | J57: 0 | K57: 2 | L57: 0 | M57: Mid | N57: =F57+G57*4*1000+H57*10000+1*1500*I57+1*J57*1000+1*K57*1000+1*L57*1000 -> 42000 | O57: WHSWBIW02S217 | P57: No | Q57: 0 | R57: WHSWSRBWBMWS182 | S57: 0 | T57: =VLOOKUP(C57, 'Pivot Table 2'!$A$1:$C$119, 3, FALSE) -> 20771.288 | U57: =(1-AA$6)*F57 -> 24000 | V57: =$AA$7 -> 500 | W57: =$AA$8 -> 4500 | X57: =U57-T57-V57-W57 -> -1771.2881 | Y57: =35% -> 0.35
A58: 57 | B58: Graphite Horizon (LR-09L-2) | C58: LR-09L-2 | D58: Yes | E58: Yes | F58: =VLOOKUP(C58, 'Pivot Table 2'!$A$1:$B$123, 2, FALSE) -> 40000 | G58: 0 | H58: 0 | I58: 0 | J58: 0 | K58: 2 | L58: 0 | M58: Solid dark | N58: =F58+G58*4*1000+H58*10000+1*1500*I58+1*J58*1000+1*K58*1000+1*L58*1000 -> 42000 | O58: WHSWBIW02S217 | P58: No | Q58: 0 | R58: WHSWSRBWBSDS179 | S58: 0 | T58: =VLOOKUP(C58, 'Pivot Table 2'!$A$1:$C$119, 3, FALSE) -> 19876.373 | U58: =(1-AA$6)*F58 -> 24000 | V58: =$AA$7 -> 500 | W58: =$AA$8 -> 4500 | X58: =U58-T58-V58-W58 -> -876.37288 | Y58: =35% -> 0.35
...

Sheet Material
A1: sno | B1: material_name | C1: material_type | D1: material_crm_code | E1: material_sap_code | F1: Price | G1: cost
A2: 1 | B2: =VLOOKUP(E2, SAP!$G$1:$V$236, 16, FALSE) -> Charcoal (PS)-Cream-Matte-PN 06167 || 8 ft x 5 inch | C2: material | D2: {=unique(Mapping!C2:C616)} -> WHSWPLCS017 | E2: WHSWPLCS017 | F2: =vlookup(E2,SAP!G$1:S$236,13,0) -> 2500 | G2: =vlookup(E2,SAP!G$1:S$236,12,0) -> 1084.0678
A3: 2 | B3: =VLOOKUP(E3, SAP!$G$1:$V$236, 16, FALSE) -> Charcoal (PS)-Pine-Wood Grain-PN 03221 || 8 ft x 5 inch | C3: material | D3: WHSWPLCS020 | E3: WHSWPLCS020 | F3: =vlookup(E3,SAP!G$1:S$236,13,0) -> 1500 | G3: =vlookup(E3,SAP!G$1:S$236,12,0) -> 595.86441
A4: 3 | B4: =VLOOKUP(E4, SAP!$G$1:$V$236, 16, FALSE) -> Charcoal (PS)-Light-Wood Grain-PN 06277 || 8 ft x 5 inch | C4: material | D4: WHSWPLCS103 | E4: WHSWPLCS103 | F4: =vlookup(E4,SAP!G$1:S$236,13,0) -> 1500 | G4: =vlookup(E4,SAP!G$1:S$236,12,0) -> 609.49153
A5: 4 | B5: =VLOOKUP(E5, SAP!$G$1:$V$236, 16, FALSE) -> Charcoal (PS)-Brown-Wood Grain-PN 03399 || 8 ft x 5 inch | C5: material | D5: WHSWPLCS079 | E5: WHSWPLCS079 | F5: =vlookup(E5,SAP!G$1:S$236,13,0) -> 2000 | G5: =vlookup(E5,SAP!G$1:S$236,12,0) -> 894.16949
A6: 5 | B6: =VLOOKUP(E6, SAP!$G$1:$V$236, 16, FALSE) -> 240 LED strip light (5m) | C6: material | D6: WHSWLTLEDS164 | E6: WHSWLTLEDS164 | F6: =vlookup(E6,SAP!G$1:S$236,13,0) -> 1500 | G6: =vlookup(E6,SAP!G$1:S$236,12,0) -> 750
A7: 6 | B7: =VLOOKUP(E7, SAP!$G$1:$V$236, 16, FALSE) -> 16X16 Alumnium Angular Profile (3m) || 16 x 16 mm | C7: material | D7: WHSWLTLEDS165 | E7: WHSWLTLEDS165 | F7: =vlookup(E7,SAP!G$1:S$236,13,0) -> 500 | G7: =vlookup(E7,SAP!G$1:S$236,12,0) -> 270
A8: 7 | B8: =VLOOKUP(E8, SAP!$G$1:$V$236, 16, FALSE) -> 10 AMP (24V) LED Power Adapter | C8: material | D8: WHSWLTLEDS167 | E8: WHSWLTLEDS167 | F8: =vlookup(E8,SAP!G$1:S$236,13,0) -> 1500 | G8: =vlookup(E8,SAP!G$1:S$236,12,0) -> 750
A9: 8 | B9: =VLOOKUP(E9, SAP!$G$1:$V$236, 16, FALSE) -> Aluminium channels reactangular 1 mm || 12 ft x 50 mm | C9: material | D9: WHSWCHALS162 | E9: WHSWCHALS162 | F9: =vlookup(E9,SAP!G$1:S$236,13,0) -> 1000 | G9: =vlookup(E9,SAP!G$1:S$236,12,0) -> 675
A10: 9 | B10: =VLOOKUP(E10, SAP!$G$1:$V$236, 16, FALSE) -> PVC board 11 mm || 8 ft x 4 ft | C10: material | D10: WHSWBDPS161 | E10: WHSWBDPS161 | F10: =vlookup(E10,SAP!G$1:S$236,13,0) -> 2500 | G10: =vlookup(E10,SAP!G$1:S$236,12,0) -> 2050
A11: 10 | B11: =VLOOKUP(E11, SAP!$G$1:$V$236, 16, FALSE) -> Wall Bidding WPC 08 | C11: material | D11: WHSWBIW08S223 | E11: WHSWBIW08S223 | F11: =vlookup(E11,SAP!G$1:S$236,13,0) -> 500 | G11: =vlookup(E11,SAP!G$1:S$236,12,0) -> 250
A12: 11 | B12: =VLOOKUP(E12, SAP!$G$1:$V$236, 16, FALSE) -> Charcoal (PS)-Dark-Wood Grain-PN 02746 || 9.5 ft x 4.8 inch | C12: material | D12: WHSWPLCS042 | E12: WHSWPLCS042 | F12: =vlookup(E12,SAP!G$1:S$236,13,0) -> 2000 | G12: =vlookup(E12,SAP!G$1:S$236,12,0) -> 819.59322
A13: 12 | B13: =VLOOKUP(E13, SAP!$G$1:$V$236, 16, FALSE) -> Wall Bidding WPC 01 | C13: material | D13: WHSWBIW01S216 | E13: WHSWBIW01S216 | F13: =vlookup(E13,SAP!G$1:S$236,13,0) -> 500 | G13: =vlookup(E13,SAP!G$1:S$236,12,0) -> 250
A14: 13 | B14: =VLOOKUP(E14, SAP!$G$1:$V$236, 16, FALSE) -> Charcoal (PS)-Walnut-Wood Grain-PN 03223 || 8 ft x 5 inch | C14: material | D14: WHSWPLCS021 | E14: WHSWPLCS021 | F14: =vlookup(E14,SAP!G$1:S$236,13,0) -> 1500 | G14: =vlookup(E14,SAP!G$1:S$236,12,0) -> 595.86441
... A94: 93 | B94: =VLOOKUP(E94, SAP!$G$1:$V$236, 16, FALSE) -> Silicon sealant glue | C94: material | D94: WHSWGLSS168 | E94: WHSWGLSS168 | F94: =vlookup(E94,SAP!G$1:S$236,13,0) -> 500 | G94: =vlookup(E94,SAP!G$1:S$236,12,0) -> 273.6

Sheet Mapping
A1: sno | B1: design_code | C1: material_crm_code | D1: material_md_code | E1: qty | F1: Price | G1: cost_price
B2: BR-1-1 | C2: WHSWPLCS017 | D2: 6167 | E2: 0 | F2: =VLOOKUP(C2, Material!$E$2:$F$94, 2, FALSE) -> 2500 | G2: =VLOOKUP(C2, Material!$E$2:$G$94, 3, FALSE) -> 1084.0678
B3: BR-1-2 | C3: WHSWPLCS020 | D3: 3221 | E3: 0 | F3: =VLOOKUP(C3, Material!$E$2:$F$94, 2, FALSE) -> 1500 | G3: =VLOOKUP(C3, Material!$E$2:$G$94, 3, FALSE) -> 595.86441
B4: BR-2-1 | C4: WHSWPLCS103 | D4: 6277 | E4: 0 | F4: =VLOOKUP(C4, Material!$E$2:$F$94, 2, FALSE) -> 1500 | G4: =VLOOKUP(C4, Material!$E$2:$G$94, 3, FALSE) -> 609.49153
B5: BR-2-2 | C5: WHSWPLCS079 | D5: 3399 | E5: 0 | F5: =VLOOKUP(C5, Material!$E$2:$F$94, 2, FALSE) -> 2000 | G5: =VLOOKUP(C5, Material!$E$2:$G$94, 3, FALSE) -> 894.16949
B6: BR-3-1 | C6: WHSWPLCS017 | D6: 6167 | E6: 5 | F6: =VLOOKUP(C6, Material!$E$2:$F$94, 2, FALSE) -> 2500 | G6: =VLOOKUP(C6, Material!$E$2:$G$94, 3, FALSE) -> 1084.0678
B7: BR-3-1 | C7: WHSWLTLEDS164 | D7: LED-1 | E7: 1 | F7: =VLOOKUP(C7, Material!$E$2:$F$94, 2, FALSE) -> 1500 | G7: =VLOOKUP(C7, Material!$E$2:$G$94, 3, FALSE) -> 750
B8: BR-3-1 | C8: WHSWLTLEDS165 | D8: AL-1 | E8: 1 | F8: =VLOOKUP(C8, Material!$E$2:$F$94, 2, FALSE) -> 500 | G8: =VLOOKUP(C8, Material!$E$2:$G$94, 3, FALSE) -> 270
B9: BR-3-1 | C9: WHSWLTLEDS167 | D9: PA-1 | E9: 1 | F9: =VLOOKUP(C9, Material!$E$2:$F$94, 2, FALSE) -> 1500 | G9: =VLOOKUP(C9, Material!$E$2:$G$94, 3, FALSE) -> 750
B10: BR-3-1 | C10: WHSWCHALS162 | D10: ALC-1 | E10: 2 | F10: =VLOOKUP(C10, Material!$E$2:$F$94, 2, FALSE) -> 1000 | G10: =VLOOKUP(C10, Material!$E$2:$G$94, 3, FALSE) -> 675
B11: BR-3-1 | C11: WHSWBDPS161 | D11: PVCBD-1 | E11: 1 | F11: =VLOOKUP(C11, Material!$E$2:$F$94, 2, FALSE) -> 2500 | G11: =VLOOKUP(C11, Material!$E$2:$G$94, 3, FALSE) -> 2050
B12: BR-3-1 | C12: WHSWBIW08S223 | D12: BD-08 | E12: 2 | F12: =VLOOKUP(C12, Material!$E$2:$F$94, 2, FALSE) -> 500 | G12: =VLOOKUP(C12, Material!$E$2:$G$94, 3, FALSE) -> 250
B13: BR-3-2 | C13: WHSWPLCS042 | D13: 2746 | E13: 5 | F13: =VLOOKUP(C13, Material!$E$2:$F$94, 2, FALSE) -> 2000 | G13: =VLOOKUP(C13, Material!$E$2:$G$94, 3, FALSE) -> 819.59322
B14: BR-3-2 | C14: WHSWLTLEDS164 | D14: LED-1 | E14: 1 | F14: =VLOOKUP(C14, Material!$E$2:$F$94, 2, FALSE) -> 1500 | G14: =VLOOKUP(C14, Material!$E$2:$G$94, 3, FALSE) -> 750
B15: BR-3-2 | C15: WHSWLTLEDS165 | D15: AL-1 | E15: 1 | F15: =VLOOKUP(C15, Material!$E$2:$F$94, 2, FALSE) -> 500 | G15: =VLOOKUP(C15, Material!$E$2:$G$94, 3, FALSE) -> 270
B16: BR-3-2 | C16: WHSWLTLEDS167 | D16: PA-1 | E16: 1 | F16: =VLOOKUP(C16, Material!$E$2:$F$94, 2, FALSE) -> 1500 | G16: =VLOOKUP(C16, Material!$E$2:$G$94, 3, FALSE) -> 750
B17: BR-3-2 | C17: WHSWCHALS162 | D17: ALC-1 | E17: 2 | F17: =VLOOKUP(C17, Material!$E$2:$F$94, 2, FALSE) -> 1000 | G17: =VLOOKUP(C17, Material!$E$2:$G$94, 3, FALSE) -> 675
B18: BR-3-2 | C18: WHSWBDPS161 | D18: PVCBD-1 | E18: 1 | F18: =VLOOKUP(C18, Material!$E$2:$F$94, 2, FALSE) -> 2500 | G18: =VLOOKUP(C18, Material!$E$2:$G$94, 3, FALSE) -> 2050
B19: BR-3-2 | C19: WHSWBIW01S216 | D19: BD-01 | E19: 2 | F19: =VLOOKUP(C19, Material!$E$2:$F$94, 2, FALSE) -> 500 | G19: =VLOOKUP(C19, Material!$E$2:$G$94, 3, FALSE) -> 250
B20: BR-4-1 | C20: WHSWPLCS021 | D20: 3223 | E20: 10 | F20: =VLOOKUP(C20, Material!$E$2:$F$94, 2, FALSE) -> 1500 | G20: =VLOOKUP(C20, Material!$E$2:$G$94, 3, FALSE) -> 595.86441
B21: BR-4-1 | C21: WHSWLTLEDS164 | D21: LED-1 | E21: 1 | F21: =VLOOKUP(C21, Material!$E$2:$F$94, 2, FALSE) -> 1500 | G21: =VLOOKUP(C21, Material!$E$2:$G$94, 3, FALSE) -> 750
B22: BR-4-1 | C22: WHSWLTLEDS165 | D22: AL-1 | E22: 1 | F22: =VLOOKUP(C22, Material!$E$2:$F$94, 2, FALSE) -> 500 | G22: =VLOOKUP(C22, Material!$E$2:$G$94, 3, FALSE) -> 270
B23: BR-4-1 | C23: WHSWLTLEDS167 | D23: PA-1 | E23: 1 | F23: =VLOOKUP(C23, Material!$E$2:$F$94, 2, FALSE) -> 1500 | G23: =VLOOKUP(C23, Material!$E$2:$G$94, 3, FALSE) -> 750
B24: BR-4-1 | C24: WHSWCHALS162 | D24: ALC-1 | E24: 2 | F24: =VLOOKUP(C24, Material!$E$2:$F$94, 2, FALSE) -> 1000 | G24: =VLOOKUP(C24, Material!$E$2:$G$94, 3, FALSE) -> 675
B25: BR-4-1 | C25: WHSWBDPS161 | D25: PVCBD-1 | E25: 2 | F25: =VLOOKUP(C25, Material!$E$2:$F$94, 2, FALSE) -> 2500 | G25: =VLOOKUP(C25, Material!$E$2:$G$94, 3, FALSE) -> 2050
B26: BR-4-1 | C26: WHSWSSBWBLWS171 | D26: SB | E26: 2 | F26: =VLOOKUP(C26, Material!$E$2:$F$94, 2, FALSE) -> 1000 | G26: =VLOOKUP(C26, Material!$E$2:$G$94, 3, FALSE) -> 250
B27: BR-4-1 | C27: WHSWSRBWBLWS181 | D27: Shelf | E27: 1 | F27: =VLOOKUP(C27, Material!$E$2:$F$94, 2, FALSE) -> 1000 | G27: =VLOOKUP(C27, Material!$E$2:$G$94, 3, FALSE) -> 250
B28: BR-4-1 | C28: WHSWBIW01S216 | D28: BD-01 | E28: 2 | F28: =VLOOKUP(C28, Material!$E$2:$F$94, 2, FALSE) -> 500 | G28: =VLOOKUP(C28, Material!$E$2:$G$94, 3, FALSE) -> 250
B29: BR-4-2 | C29: WHSWPLCS055 | D29: 5656 | E29: 10 | F29: =VLOOKUP(C29, Material!$E$2:$F$94, 2, FALSE) -> 2000 | G29: =VLOOKUP(C29, Material!$E$2:$G$94, 3, FALSE) -> 968.74576
B30: BR-4-2 | C30: WHSWLTLEDS164 | D30: LED-1 | E30: 1 | F30: =VLOOKUP(C30, Material!$E$2:$F$94, 2, FALSE) -> 1500 | G30: =VLOOKUP(C30, Material!$E$2:$G$94, 3, FALSE) -> 750
B31: BR-4-2 | C31: WHSWLTLEDS165 | D31: AL-1 | E31: 1 | F31: =VLOOKUP(C31, Material!$E$2:$F$94, 2, FALSE) -> 500 | G31: =VLOOKUP(C31, Material!$E$2:$G$94, 3, FALSE) -> 270
B32: BR-4-2 | C32: WHSWLTLEDS167 | D32: PA-1 | E32: 1 | F32: =VLOOKUP(C32, Material!$E$2:$F$94, 2, FALSE) -> 1500 | G32: =VLOOKUP(C32, Material!$E$2:$G$94, 3, FALSE) -> 750
B33: BR-4-2 | C33: WHSWCHALS162 | D33: ALC-1 | E33: 2 | F33: =VLOOKUP(C33, Material!$E$2:$F$94, 2, FALSE) -> 1000 | G33: =VLOOKUP(C33, Material!$E$2:$G$94, 3, FALSE) -> 675
B34: BR-4-2 | C34: WHSWBDPS161 | D34: PVCBD-1 | E34: 2 | F34: =VLOOKUP(C34, Material!$E$2:$F$94, 2, FALSE) -> 2500 | G34: =VLOOKUP(C34, Material!$E$2:$G$94, 3, FALSE) -> 2050
B35: BR-4-2 | C35: WHSWSSBWBLWS171 | D35: SB | E35: 2 | F35: =VLOOKUP(C35, Material!$E$2:$F$94, 2, FALSE) -> 1000 | G35: =VLOOKUP(C35, Material!$E$2:$G$94, 3, FALSE) -> 250
B36: BR-4-2 | C36: WHSWSRBWBLWS181 | D36: Shelf | E36: 1 | F36: =VLOOKUP(C36, Material!$E$2:$F$94, 2, FALSE) -> 1000 | G36: =VLOOKUP(C36, Material!$E$2:$G$94, 3, FALSE) -> 250
B37: BR-4-2 | C37: WHSWBIW03S218 | D37: BD-03 | E37: 2 | F37: =VLOOKUP(C37, Material!$E$2:$F$94, 2, FALSE) -> 500 | G37: =VLOOKUP(C37, Material!$E$2:$G$94, 3, FALSE) -> 250
B38: BR-5-1 | C38: WHSWPLCS106 | D38: 3889 | E38: 20 | F38: =VLOOKUP(C38, Material!$E$2:$F$94, 2, FALSE) -> 1500 | G38: =VLOOKUP(C38, Material!$E$2:$G$94, 3, FALSE) -> 745.01695
B39: BR-5-2 | C39: WHSWPLCS020 | D39: 3221 | E39: 20 | F39: =VLOOKUP(C39, Material!$E$2:$F$94, 2, FALSE) -> 1500 | G39: =VLOOKUP(C39, Material!$E$2:$G$94, 3, FALSE) -> 595.86441
B40: BR-6-1 | C40: WHSWPLCS025 | D40: 545 | E40: 20 | F40: =VLOOKUP(C40, Material!$E$2:$F$94, 2, FALSE) -> 2000 | G40: =VLOOKUP(C40, Material!$E$2:$G$94, 3, FALSE) -> 819.59322
...

Sheet Pivot Table 1
H1: Product name
H2: =VLOOKUP(B2,SAP!G$1:H$236,2,FALSE()) -> Silicon sealant glue nail free
H3: =VLOOKUP(B3,SAP!G$1:H$236,2,FALSE()) -> Silicon sealant glue nail free
H4: =VLOOKUP(B4,SAP!G$1:H$236,2,FALSE()) -> Silicon sealant glue nail free
H5: =VLOOKUP(B5,SAP!G$1:H$236,2,FALSE()) -> PVC board 11 mm (8 X 4) | I5: Basic | J5: 30000
H6: =VLOOKUP(B6,SAP!G$1:H$236,2,FALSE()) -> Wall Bidding WPC 02 | I6: Light | J6: 11500
H7: =VLOOKUP(B7,SAP!G$1:H$236,2,FALSE()) -> Aluminium channels reactangular 1 mm
H8: =VLOOKUP(B8,SAP!G$1:H$236,2,FALSE()) -> Silicon sealant glue nail free
H9: =VLOOKUP(B9,SAP!G$1:H$236,2,FALSE()) -> 240 LED strip light 5m
H10: =VLOOKUP(B10,SAP!G$1:H$236,2,FALSE()) -> 10 AMP 24V LED Power Adapter
H11: =VLOOKUP(B11,SAP!G$1:H$236,2,FALSE()) -> Brown Wooden Louver PN 02307 CPC Panel
H12: =VLOOKUP(B12,SAP!G$1:H$236,2,FALSE()) -> Silicon sealant glue nail free
H13: =VLOOKUP(B13,SAP!G$1:H$236,2,FALSE()) -> Silicon sealant glue nail free
H14: =VLOOKUP(B14,SAP!G$1:H$236,2,FALSE()) -> PVC board 11 mm (8 X 4) | I14: Basic | J14: 18000
H15: =VLOOKUP(B15,SAP!G$1:H$236,2,FALSE()) -> Wall Bidding WPC 02 | I15: Light | J15: 14000
H16: =VLOOKUP(B16,SAP!G$1:H$236,2,FALSE()) -> Aluminium channels reactangular 1 mm | I16: Storage | J16: 3000
H17: =VLOOKUP(B17,SAP!G$1:H$236,2,FALSE()) -> Silicon sealant glue nail free
H18: =VLOOKUP(B18,SAP!G$1:H$236,2,FALSE()) -> 240 LED strip light 5m
H19: =VLOOKUP(B19,SAP!G$1:H$236,2,FALSE()) -> 16X16 Alumnium Angular Profile 3m
H20: =VLOOKUP(B20,SAP!G$1:H$236,2,FALSE()) -> 10 AMP 24V LED Power Adapter
H21: =VLOOKUP(B21,SAP!G$1:H$236,2,FALSE()) -> Charcoal PS-Cream-Matte-PN 05667
H22: =VLOOKUP(B22,SAP!G$1:H$236,2,FALSE()) -> Wall storage 300mm shelf light woodgrain
H23: =VLOOKUP(B23,SAP!G$1:H$236,2,FALSE()) -> Rangular box wo backpanel lightwoodgrain
H24: =VLOOKUP(B24,SAP!G$1:H$236,2,FALSE()) -> Silicon sealant glue nail free
H25: =VLOOKUP(B25,SAP!G$1:H$236,2,FALSE()) -> Charcoal PS-Walnut-Wood Grain-PN 02347
H26: =VLOOKUP(B26,SAP!G$1:H$236,2,FALSE()) -> Silicon sealant glue nail free
H27: =VLOOKUP(B27,SAP!G$1:H$236,2,FALSE()) -> Silicon sealant glue nail free
H28: =VLOOKUP(B28,SAP!G$1:H$236,2,FALSE()) -> PVC board 11 mm (8 X 4) | I28: Basic | J28: 22500
H29: =VLOOKUP(B29,SAP!G$1:H$236,2,FALSE()) -> Wall Bidding WPC 02 | I29: Storage | J29: 5000
H30: =VLOOKUP(B30,SAP!G$1:H$236,2,FALSE()) -> Aluminium channels reactangular 1 mm | I30: Light | J30: 10500
H31: =VLOOKUP(B31,SAP!G$1:H$236,2,FALSE()) -> Silicon sealant glue nail free
H32: =VLOOKUP(B32,SAP!G$1:H$236,2,FALSE()) -> 240 LED strip light 5m
H33: =VLOOKUP(B33,SAP!G$1:H$236,2,FALSE()) -> 16X16 Alumnium Angular Profile 3m
H34: =VLOOKUP(B34,SAP!G$1:H$236,2,FALSE()) -> 10 AMP 24V LED Power Adapter
H35: =VLOOKUP(B35,SAP!G$1:H$236,2,FALSE()) -> Brown Wooden Louver PN 02308 - CPC Panel
H36: =VLOOKUP(B36,SAP!G$1:H$236,2,FALSE()) -> Wall storage 300mm shelf light woodgrain
H37: =VLOOKUP(B37,SAP!G$1:H$236,2,FALSE()) -> Square box wo backpanel mid wood grain
H38: =VLOOKUP(B38,SAP!G$1:H$236,2,FALSE()) -> Wall Trim 6 mm SS: Black Glossy
H39: =VLOOKUP(B39,SAP!G$1:H$236,2,FALSE()) -> PVC board 11 mm (8 X 4) | I39: Basic | J39: 22500
H40: =VLOOKUP(B40,SAP!G$1:H$236,2,FALSE()) -> Wall Bidding WPC 02 | I40: Storage | J40: 5000
...

Sheet Pivot Table 2

Sheet SAP
A1: Revenue Segment | B1: Product Type/ Generic Name | C1: Country of Origin | D1: Parent SKU Code | E1: Parent Product Name | F1: Characters Length (40 Characters) | G1: Child SKU Code | H1: Child Product Name | I1: Characters Length (40 Characters) | J1: UOM | K1: Packing Dimensions (MM) (LXWXH) | L1: Product Dimensions (MM) (LXWXH) | M1: Gross Weight (KG) | N1: Net Weight (KG) | O1: HSN Code | P1: Conversion Factor | Q1: Plant | R1: MAP (Child) | S1: MRP | T1: SAP Code Parent | U1: SAP Code child | V1: Product Name with size
A2: HIF | B2: Wall Panel | C2: India | G2: WHSWPLPS001 | H2: PVC-Wooden/Multi-clr-Wood Grain-PN 06186 | I2: =len(H2) -> 40 | J2: N | K2: 3048 x 254 x 6 | L2: =K2 -> 3048 x 254 x 6 | M2: 2.5 | N2: 2.5 | O2: 39259090 | P2: 1 | Q2: KA04,MTN9 | R2: 1043.322 | S2: =2500 -> 2500 | V2: PVC-Wooden/Multi-clr-Wood Grain-PN 06186 || 10 ft x 10 inch
A3: HIF | B3: Wall Panel | C3: India | G3: WHSWPLPS002 | H3: PVC-Walnut/Dark Wood-Wood Grain-PN 00402 | I3: =len(H3) -> 40 | J3: N | K3: 3048 x 254 x 6 | L3: =K3 -> 3048 x 254 x 6 | M3: 2.5 | N3: 2.5 | O3: 39259090 | P3: 1 | Q3: KA04,MTN9 | R3: 335.60169 | S3: =700 -> 700 | V3: PVC-Walnut/Dark Wood-Wood Grain-PN 00402 || 10 ft x 10 inch
A4: HIF | B4: Wall Panel | C4: India | G4: WHSWPLWS003 | H4: WPC-Natural Wood-Wood Grain-PN 00273 | I4: =len(H4) -> 36 | J4: N | K4: 2895.6 x 127 x 12 | L4: =K4 -> 2895.6 x 127 x 12 | M4: 4 | N4: 4 | O4: 39259090 | P4: 1 | Q4: KA04,MTN9 | R4: 648.80508 | S4: =1500 -> 1500 | V4: WPC-Natural Wood-Wood Grain-PN 00273 || 9.5 ft x 5 inch
A5: HIF | B5: Wall Panel | C5: India | G5: WHSWPLWS004 | H5: WPC-Charcoal Grey-Matte-PN 02898 | I5: =len(H5) -> 32 | J5: N | K5: 2895.6 x 127 x 12 | L5: =K5 -> 2895.6 x 127 x 12 | M5: 4 | N5: 4 | O5: 39259090 | P5: 1 | Q5: KA04,MTN9 | R5: 648.80508 | S5: =1500 -> 1500 | V5: WPC-Charcoal Grey-Matte-PN 02898 || 9.5 ft x 5 inch
A6: HIF | B6: Wall Panel | C6: India | G6: WHSWPLWS005 | H6: WPC-Black-Matte-PN 02912 | I6: =len(H6) -> 24 | J6: N | K6: 2895.6 x 127 x 12 | L6: =K6 -> 2895.6 x 127 x 12 | M6: 4 | N6: 4 | O6: 39259090 | P6: 1 | Q6: KA04,MTN9 | R6: 648.80508 | S6: =1500 -> 1500 | V6: WPC-Black-Matte-PN 02912 || 9.5 ft x 5 inch
A7: HIF | B7: Wall Panel | C7: India | G7: WHSWPLCS006 | H7: Charcoal PS-Beige-Matte-PN 03851 | I7: =len(H7) -> 32 | J7: N | K7: 2895.6 x 152.4 x 10 | L7: =K7 -> 2895.6 x 152.4 x 10 | M7: 1.5 | N7: 1.5 | O7: 39269099 | P7: 1 | Q7: KA04,MTN9 | R7: 648.80508 | S7: 1500 | V7: Charcoal (PS)-Beige-Matte-PN 03851 || 9.5 ft x 6 inch
A8: HIF | B8: Wall Panel | C8: India | G8: WHSWPLCS007 | H8: Charcoal PS-Grey-Matte-PN 03856 | I8: =len(H8) -> 31 | J8: N | K8: 2895.6 x 152.4 x 10 | L8: =K8 -> 2895.6 x 152.4 x 10 | M8: 1.5 | N8: 1.5 | O8: 39269099 | P8: 1 | Q8: KA04,MTN9 | R8: 745.01695 | S8: =1500 -> 1500 | V8: Charcoal (PS)-Grey-Matte-PN 03856 || 9.5 ft x 6 inch
A9: HIF | B9: Wall Panel | C9: India | G9: WHSWPLCS008 | H9: Charcoal PS-Walnut-Wood Grain-PN 03864 | I9: =len(H9) -> 38 | J9: N | K9: 2895.6 x 152.4 x 10 | L9: =K9 -> 2895.6 x 152.4 x 10 | M9: 1.5 | N9: 1.5 | O9: 39269099 | P9: 1 | Q9: KA04,MTN9 | R9: 819.59322 | S9: =2000 -> 2000 | V9: Charcoal (PS)-Walnut-Wood Grain-PN 03864 || 9.5 ft x 6 inch
A10: HIF | B10: Wall Panel | C10: India | G10: WHSWPLCS009 | H10: Charcoal PS-Pine-Wood Grain-PN 03865 | I10: =len(H10) -> 36 | J10: N | K10: 2895.6 x 152.4 x 10 | L10: =K10 -> 2895.6 x 152.4 x 10 | M10: 1.5 | N10: 1.5 | O10: 39269099 | P10: 1 | Q10: KA04,MTN9 | R10: 819.59322 | S10: =2000 -> 2000 | V10: Charcoal (PS)-Pine-Wood Grain-PN 03865 || 9.5 ft x 6 inch
A11: HIF | B11: Wall Panel | C11: India | G11: WHSWPLCS010 | H11: Charcoal PS-Teak-Wood Grain-PN 03044 | I11: =len(H11) -> 36 | J11: N | K11: 2438.4 x 127 x 12 | L11: =K11 -> 2438.4 x 127 x 12 | M11: 1.5 | N11: 1.5 | O11: 39269099 | P11: 1 | Q11: KA04,MTN9 | R11: 670.44068 | S11: 1500 | V11: Charcoal (PS)-Teak-Wood Grain-PN 03044 || 8 ft x 5 inch
A12: HIF | B12: Wall Panel | C12: India | G12: WHSWPLCS011 | H12: Charcoal PS-Grey-Matte-PN 00901 | I12: =len(H12) -> 31 | J12: N | K12: 2438.4 x 127 x 12 | L12: =K12 -> 2438.4 x 127 x 12 | M12: 1.5 | N12: 1.5 | O12: 392690 | P12: 1 | Q12: KA04,MTN9 | R12: 819.59322 | S12: =2000 -> 2000 | V12: Charcoal (PS)-Grey-Matte-PN 00901 || 8 ft x 5 inch
A13: HIF | B13: Wall Panel | C13: India | G13: WHSWPLCS012 | H13: Charcoal PS-Walnut-Wood Grain-PN 03043 | I13: =len(H13) -> 38 | J13: N | K13: 2438.4 x 127 x 12 | L13: =K13 -> 2438.4 x 127 x 12 | M13: 1.5 | N13: 1.5 | O13: 39269099 | P13: 1 | Q13: KA04,MTN9 | R13: 670.44068 | S13: 1500 | V13: Charcoal (PS)-Walnut-Wood Grain-PN 03043 || 8 ft x 5 inch
A14: HIF | B14: Wall Panel | C14: India | G14: WHSWPLCS013 | H14: Charcoal PS-Brown-Wood Grain-PN 05777 | I14: =len(H14) -> 37 | J14: N | K14: 2438.4 x 127 x 11 | L14: =K14 -> 2438.4 x 127 x 11 | M14: 1.5 | N14: 1.5 | O14: 39269099 | P14: 1 | Q14: KA04,MTN9 | R14: 1192.4746 | S14: =2500 -> 2500 | V14: Charcoal (PS)-Brown-Wood Grain-PN 05777 || 8 ft x 5 inch
A15: HIF | B15: Wall Panel | C15: India | G15: WHSWPLCS014 | H15: Charcoal PS-Teak-Wood Grain-PN 06161 | I15: =len(H15) -> 36 | J15: N | K15: 2438.4 x 127 x 11 | L15: =K15 -> 2438.4 x 127 x 11 | M15: 1.5 | N15: 1.5 | O15: 39269099 | P15: 1 | Q15: KA04,MTN9 | R15: 1084.0678 | S15: 2500 | V15: Charcoal (PS)-Teak-Wood Grain-PN 06161 || 8 ft x 5 inch
A16: HIF | B16: Wall Panel | C16: India | G16: WHSWPLCS015 | H16: Charcoal PS-Pine-Wood Grain-PN 06158 | I16: =len(H16) -> 36 | J16: N | K16: 2438.4 x 127 x 11 | L16: =K16 -> 2438.4 x 127 x 11 | M16: 1.5 | N16: 1.5 | O16: 39269099 | P16: 1 | Q16: KA04,MTN9 | R16: 1192.4746 | S16: =2500 -> 2500 | V16: Charcoal (PS)-Pine-Wood Grain-PN 06158 || 8 ft x 5 inch
A17: HIF | B17: Wall Panel | C17: India | G17: WHSWPLCS016 | H17: Charcoal PS-Black-Matte-PN 06159 | I17: =len(H17) -> 32 | J17: N | K17: 2438.4 x 127 x 11 | L17: =K17 -> 2438.4 x 127 x 11 | M17: 1.5 | N17: 1.5 | O17: 39269099 | P17: 1 | Q17: KA04,MTN9 | R17: 1084.0678 | S17: 2500 | V17: Charcoal (PS)-Black-Matte-PN 06159 || 8 ft x 5 inch
A18: HIF | B18: Wall Panel | C18: India | G18: WHSWPLCS017 | H18: Charcoal PS-Cream-Matte-PN 06167 | I18: =len(H18) -> 32 | J18: N | K18: 2438.4 x 127 x 11 | L18: =K18 -> 2438.4 x 127 x 11 | M18: 1.5 | N18: 1.5 | O18: 39269099 | P18: 1 | Q18: KA04,MTN9 | R18: 1084.0678 | S18: 2500 | V18: Charcoal (PS)-Cream-Matte-PN 06167 || 8 ft x 5 inch
A19: HIF | B19: Wall Panel | C19: India | G19: WHSWPLCS018 | H19: Charcoal PS-Ivory-Matte-PN 06156 | I19: =len(H19) -> 32 | J19: N | K19: 2438.4 x 127 x 11 | L19: =K19 -> 2438.4 x 127 x 11 | M19: 1.5 | N19: 1.5 | O19: 39269099 | P19: 1 | Q19: KA04,MTN9 | R19: 1084.0678 | S19: 2500 | V19: Charcoal (PS)-Ivory-Matte-PN 06156 || 8 ft x 5 inch
A20: HIF | B20: Wall Panel | C20: India | G20: WHSWPLCS019 | H20: Charcoal PS-Dark-Wood Grain-PN 03208 | I20: =len(H20) -> 36 | J20: N | K20: 2438.4 x 127 x 11 | L20: =K20 -> 2438.4 x 127 x 11 | M20: 1.5 | N20: 1.5 | O20: 39269099 | P20: 1 | Q20: KA04,MTN9 | R20: 595.86441 | S20: 1500 | V20: Charcoal (PS)-Dark-Wood Grain-PN 03208 || 8 ft x 5 inch
A21: HIF | B21: Wall Panel | C21: India | G21: WHSWPLCS020 | H21: Charcoal PS-Pine-Wood Grain-PN 03221 | I21: =len(H21) -> 36 | J21: N | K21: 2438.4 x 127 x 11 | L21: =K21 -> 2438.4 x 127 x 11 | M21: 1.5 | N21: 1.5 | O21: 39269099 | P21: 1 | Q21: KA04,MTN9 | R21: 595.86441 | S21: 1500 | V21: Charcoal (PS)-Pine-Wood Grain-PN 03221 || 8 ft x 5 inch
A22: HIF | B22: Wall Panel | C22: India | G22: WHSWPLCS021 | H22: Charcoal PS-Walnut-Wood Grain-PN 03223 | I22: =len(H22) -> 38 | J22: N | K22: 2438.4 x 127 x 11 | L22: =K22 -> 2438.4 x 127 x 11 | M22: 1.5 | N22: 1.5 | O22: 39269099 | P22: 1 | Q22: KA04,MTN9 | R22: 595.86441 | S22: 1500 | V22: Charcoal (PS)-Walnut-Wood Grain-PN 03223 || 8 ft x 5 inch
A23: HIF | B23: Wall Panel | C23: India | G23: WHSWPLCS022 | H23: Charcoal PS-Teak-Wood Grain-PN 03222 | I23: =len(H23) -> 36 | J23: N | K23: 2438.4 x 127 x 11 | L23: =K23 -> 2438.4 x 127 x 11 | M23: 1.5 | N23: 1.5 | O23: 39269099 | P23: 1 | Q23: KA04,MTN9 | R23: 595.86441 | S23: 1500 | V23: Charcoal (PS)-Teak-Wood Grain-PN 03222 || 8 ft x 5 inch
A24: HIF | B24: Wall Panel | C24: India | G24: WHSWPLCS023 | H24: Charcoal PS-Grey-Matte-PN 03210 | I24: =len(H24) -> 31 | J24: N | K24: 2438.4 x 127 x 11 | L24: =K24 -> 2438.4 x 127 x 11 | M24: 1.5 | N24: 1.5 | O24: 39269099 | P24: 1 | Q24: KA04,MTN9 | R24: 595.86441 | S24: 1500 | V24: Charcoal (PS)-Grey-Matte-PN 03210 || 8 ft x 5 inch
A25: HIF | B25: Wall Panel | C25: India | G25: WHSWPLCS024 | H25: Charcoal PS-Oak-Wood Grain-PN 05610 | I25: =len(H25) -> 35 | J25: N | K25: 2438.4 x 127 x 11 | L25: =K25 -> 2438.4 x 127 x 11 | M25: 1.5 | N25: 1.5 | O25: 39269099 | P25: 1 | Q25: KA04,MTN9 | R25: 670.44068 | S25: 1500 | V25: Charcoal (PS)-Oak-Wood Grain-PN 05610 || 8 ft x 5 inch
A26: HIF | B26: Wall Panel | C26: India | G26: WHSWPLCS025 | H26: Charcoal PS-Dark Grey-Matte-PN 00545 | I26: =len(H26) -> 36 | J26: N | K26: 2438.4 x 127 x 11 | L26: =K26 -> 2438.4 x 127 x 11 | M26: 1.5 | N26: 1.5 | O26: 392690 | P26: 1 | Q26: KA04,MTN9 | R26: 819.59322 | S26: =2000 -> 2000 | V26: Charcoal (PS)-Dark Grey-Matte-PN 00545 || 8 ft x 5 inch
A27: HIF | B27: Wall Panel | C27: India | G27: WHSWPLCS026 | H27: Charcoal PS-Pine-Wood Grain-PN 05291 | I27: =len(H27) -> 36 | J27: N | K27: 2438.4 x 127 x 11 | L27: =K27 -> 2438.4 x 127 x 11 | M27: 1.5 | N27: 1.5 | O27: 39269099 | P27: 1 | Q27: KA04,MTN9 | R27: 595.86441 | S27: 1500 | V27: Charcoal (PS)-Pine-Wood Grain-PN 05291 || 8 ft x 5 inch
A28: HIF | B28: Wall Panel | C28: India | G28: WHSWPLCS027 | H28: Charcoal PS-Walnut-Wood Grain-PN 05289 | I28: =len(H28) -> 38 | J28: N | K28: 2438.4 x 127 x 11 | L28: =K28 -> 2438.4 x 127 x 11 | M28: 1.5 | N28: 1.5 | O28: 39269099 | P28: 1 | Q28: KA04,MTN9 | R28: 595.86441 | S28: 1500 | V28: Charcoal (PS)-Walnut-Wood Grain-PN 05289 || 8 ft x 5 inch
A29: HIF | B29: Wall Panel | C29: India | G29: WHSWPLCS028 | H29: Charcoal PS-Multi-Wood Grain-PN 06288 | I29: =len(H29) -> 37 | J29: N | K29: 2438.4 x 127 x 11 | L29: =K29 -> 2438.4 x 127 x 11 | M29: 1.5 | N29: 1.5 | O29: 39269099 | P29: 1 | Q29: KA04,MTN9 | R29: 745.01695 | S29: =1500 -> 1500 | V29: Charcoal (PS)-Multi-Wood Grain-PN 06288 || 8 ft x 5 inch
A30: HIF | B30: Wall Panel | C30: India | G30: WHSWPLCS029 | H30: Charcoal PS-White-Matte-PN 00155 | I30: =len(H30) -> 32 | J30: N | K30: 2438.4 x 127 x 11 | L30: =K30 -> 2438.4 x 127 x 11 | M30: 1.5 | N30: 1.5 | O30: 39269099 | P30: 1 | Q30: KA04,MTN9 | R30: 670.44068 | S30: 1500 | V30: Charcoal (PS)-White-Matte-PN 00155 || 8 ft x 5 inch
A31: HIF | B31: Wall Panel | C31: India | G31: WHSWPLCS030 | H31: Charcoal PS-Medium-Wood Grain-PN 05514 | I31: =len(H31) -> 38 | J31: N | K31: 2438.4 x 127 x 11 | L31: =K31 -> 2438.4 x 127 x 11 | M31: 1.5 | N31: 1.5 | O31: 39269099 | P31: 1 | Q31: KA04,MTN9 | R31: 595.86441 | S31: 1500 | V31: Charcoal (PS)-Medium-Wood Grain-PN 05514 || 8 ft x 5 inch
A32: HIF | B32: Wall Panel | C32: India | G32: WHSWPLCS031 | H32: Charcoal PS-Teak-Wood Grain-PN 00140 | I32: =len(H32) -> 36 | J32: N | K32: 2438.4 x 127 x 11 | L32: =K32 -> 2438.4 x 127 x 11 | M32: 1.5 | N32: 1.5 | O32: 39269099 | P32: 1 | Q32: KA04,MTN9 | R32: 677.28814 | S32: =1500 -> 1500 | V32: Charcoal (PS)-Teak-Wood Grain-PN 00140 || 8 ft x 5 inch
A33: HIF | B33: Wall Panel | C33: India | G33: WHSWPLCS032 | H33: Charcoal PS-Dark-Wood Grain-PN 05484 | I33: =len(H33) -> 36 | J33: N | K33: 2438.4 x 127 x 11 | L33: =K33 -> 2438.4 x 127 x 11 | M33: 1.5 | N33: 1.5 | O33: 39269099 | P33: 1 | Q33: KA04,MTN9 | R33: 595.86441 | S33: 1500 | V33: Charcoal (PS)-Dark-Wood Grain-PN 05484 || 8 ft x 5 inch
A34: HIF | B34: Wall Panel | C34: India | G34: WHSWPLCS033 | H34: Charcoal PS-Pine-Wood Grain-PN 00147 | I34: =len(H34) -> 36 | J34: N | K34: 2438.4 x 127 x 11 | L34: =K34 -> 2438.4 x 127 x 11 | M34: 1.5 | N34: 1.5 | O34: 39269099 | P34: 1 | Q34: KA04,MTN9 | R34: 670.44068 | S34: 1500 | V34: Charcoal (PS)-Pine-Wood Grain-PN 00147 || 8 ft x 5 inch
A35: HIF | B35: Wall Panel | C35: India | G35: WHSWPLCS034 | H35: Charcoal PS-Oak-Wood Grain-PN 05606 | I35: =len(H35) -> 35 | J35: N | K35: 2438.4 x 127 x 11 | L35: =K35 -> 2438.4 x 127 x 11 | M35: 1.5 | N35: 1.5 | O35: 39269099 | P35: 1 | Q35: KA04,MTN9 | R35: 670.44068 | S35: 1500 | V35: Charcoal (PS)-Oak-Wood Grain-PN 05606 || 8 ft x 5 inch
A36: HIF | B36: Wall Panel | C36: India | G36: WHSWPLCS035 | H36: Charcoal PS-Teak-Wood Grain-PN 02343 | I36: =len(H36) -> 36 | J36: N | K36: 2438.4 x 609.6 x 10 | L36: =K36 -> 2438.4 x 609.6 x 10 | M36: 10 | N36: 10 | O36: 39269099 | P36: 1 | Q36: KA04,MTN9 | R36: 1117.8983 | S36: 2500 | V36: Charcoal (PS)-Teak-Wood Grain-PN 02343 || 8 ft x 2 ft
A37: HIF | B37: Wall Panel | C37: India | G37: WHSWPLCS036 | H37: Charcoal PS-Walnut-Wood Grain-PN 02347 | I37: =len(H37) -> 38 | J37: N | K37: 2438.4 x 609.6 x 10 | L37: =K37 -> 2438.4 x 609.6 x 10 | M37: 10 | N37: 10 | O37: 39269099 | P37: 1 | Q37: KA04,MTN9 | R37: 1117.8983 | S37: 2500 | V37: Charcoal (PS)-Walnut-Wood Grain-PN 02347 || 8 ft x 2 ft
A38: HIF | B38: Wall Panel | C38: India | G38: WHSWPLCS037 | H38: Charcoal PS-Grey-Matte-PN 02341 | I38: =len(H38) -> 31 | J38: N | K38: 2438.4 x 609.6 x 10 | L38: =K38 -> 2438.4 x 609.6 x 10 | M38: 10 | N38: 10 | O38: 39269099 | P38: 1 | Q38: KA04,MTN9 | R38: 1016.2712 | S38: 2500 | V38: Charcoal (PS)-Grey-Matte-PN 02341 || 8 ft x 2 ft
A39: HIF | B39: Wall Panel | C39: India | G39: WHSWPLCS038 | H39: Charcoal PS-Beige-Matte-PN 02345 B | I39: =len(H39) -> 34 | J39: N | K39: 2438.4 x 609.6 x 10 | L39: =K39 -> 2438.4 x 609.6 x 10 | M39: 10 | N39: 10 | O39: 39269099 | P39: 1 | Q39: KA04,MTN9 | R39: 670.44068 | S39: 1500 | V39: Charcoal (PS)-Beige-Matte-PN 02345 B || 8 ft x 2 ft
A40: HIF | B40: Wall Panel | C40: India | G40: WHSWPLCS039 | H40: Charcoal PS-Black-Matte-PN 02346 | I40: =len(H40) -> 32 | J40: N | K40: 2438.4 x 609.6 x 10 | L40: =K40 -> 2438.4 x 609.6 x 10 | M40: 10 | N40: 10 | O40: 39269099 | P40: 1 | Q40: KA04,MTN9 | R40: 670.44068 | S40: 1500 | V40: Charcoal (PS)-Black-Matte-PN 02346 || 8 ft x 2 ft
...

Sheet Copy of Designs
A1: Sno | B1: design_name | C1: design_code | D1: published | E1: active
A2: 1 | B2: BR-1-1 | C2: BR-1-1 | D2: No | E2: Yes
A3: 2 | B3: BR-1-2 | C3: BR-1-2 | D3: No | E3: Yes
A4: 3 | B4: BR-2-1 | C4: BR-2-1 | D4: No | E4: Yes
A5: 4 | B5: BR-2-2 | C5: BR-2-2 | D5: No | E5: Yes
A6: 5 | B6: Noctis Haven (BR-3-1) | C6: BR-3-1 | D6: Yes | E6: Yes
A7: 6 | B7: Caelum Nest (BR-3-2) | C7: BR-3-2 | D7: Yes | E7: Yes
A8: 7 | B8: Amber Silence (BR-4-1) | C8: BR-4-1 | D8: Yes | E8: Yes
A9: 8 | B9: Elaris Woodline (BR-4-2) | C9: BR-4-2 | D9: Yes | E9: Yes
A10: 9 | B10: BR-5-1 | C10: BR-5-1 | D10: No | E10: Yes
A11: 10 | B11: BR-5-2 | C11: BR-5-2 | D11: No | E11: Yes
A12: 11 | B12: Solstice Haven (BR-6-1) | C12: BR-6-1 | D12: Yes | E12: Yes
A13: 12 | B13: Morvane Essence (BR-6-2) | C13: BR-6-2 | D13: Yes | E13: Yes
... A122: 121 | B122: Velorian Nest (BR-39) | C122: BR-39 | D122: Yes | E122: Yes

Sheet Copy of Material
A1: sno | B1: material_name | C1: material_type | D1: material_crm_code | E1: material_sap_code | F1: Price
A2: 1 | B2: Charcoal (PS)-Cream-Matte-PN 06167 || 8 ft x 5 inch | C2: material | D2: WHSWPLCS017 | E2: WHSWPLCS017 | F2: 2500
A3: 2 | B3: Charcoal (PS)-Pine-Wood Grain-PN 03221 || 8 ft x 5 inch | C3: material | D3: WHSWPLCS020 | E3: WHSWPLCS020 | F3: 1500
A4: 3 | B4: Charcoal (PS)-Light-Wood Grain-PN 06277 || 8 ft x 5 inch | C4: material | D4: WHSWPLCS103 | E4: WHSWPLCS103 | F4: 1500
A5: 4 | B5: Charcoal (PS)-Brown-Wood Grain-PN 03399 || 8 ft x 5 inch | C5: material | D5: WHSWPLCS079 | E5: WHSWPLCS079 | F5: 2000
A6: 5 | B6: 240 LED strip light (5m) | C6: material | D6: WHSWLTLEDS164 | E6: WHSWLTLEDS164 | F6: 1500
A7: 6 | B7: 16X16 Alumnium Angular Profile (3m) || 16 x 16 mm | C7: material | D7: WHSWLTLEDS165 | E7: WHSWLTLEDS165 | F7: 500
A8: 7 | B8: 10 AMP (24V) LED Power Adapter | C8: material | D8: WHSWLTLEDS167 | E8: WHSWLTLEDS167 | F8: 1500
A9: 8 | B9: Aluminium channels reactangular 1 mm || 12 ft x 50 mm | C9: material | D9: WHSWCHALS162 | E9: WHSWCHALS162 | F9: 1000
A10: 9 | B10: PVC board 11 mm || 8 ft x 4 ft | C10: material | D10: WHSWBDPS161 | E10: WHSWBDPS161 | F10: 2500
A11: 10 | B11: Wall Bidding WPC 08 | C11: material | D11: WHSWBIW08S223 | E11: WHSWBIW08S223 | F11: 500
A12: 11 | B12: Charcoal (PS)-Dark-Wood Grain-PN 02746 || 9.5 ft x 4.8 inch | C12: material | D12: WHSWPLCS042 | E12: WHSWPLCS042 | F12: 2000
A13: 12 | B13: Wall Bidding WPC 01 | C13: material | D13: WHSWBIW01S216 | E13: WHSWBIW01S216 | F13: 500
... A94: 93 | B94: Silicon sealant glue | C94: material | D94: WHSWGLSS168 | E94: WHSWGLSS168 | F94: 500

Sheet Copy of Mapping
A1: sno | B1: design_code | C1: material_crm_code | D1: material_md_code | E1: qty | F1: Price
B2: BR-1-1 | C2: WHSWPLCS017 | D2: 6167 | E2: 0 | F2: 2500
B3: BR-1-2 | C3: WHSWPLCS020 | D3: 3221 | E3: 0 | F3: 1500
B4: BR-2-1 | C4: WHSWPLCS103 | D4: 6277 | E4: 0 | F4: 1500
B5: BR-2-2 | C5: WHSWPLCS079 | D5: 3399 | E5: 0 | F5: 2000
B6: BR-3-1 | C6: WHSWPLCS017 | D6: 6167 | E6: 5 | F6: 2500
B7: BR-3-1 | C7: WHSWLTLEDS164 | D7: LED-1 | E7: 1 | F7: 1500
B8: BR-3-1 | C8: WHSWLTLEDS165 | D8: AL-1 | E8: 1 | F8: 500
B9: BR-3-1 | C9: WHSWLTLEDS167 | D9: PA-1 | E9: 1 | F9: 1500
B10: BR-3-1 | C10: WHSWCHALS162 | D10: ALC-1 | E10: 2 | F10: 1000
B11: BR-3-1 | C11: WHSWBDPS161 | D11: PVCBD-1 | E11: 1 | F11: 2500
B12: BR-3-1 | C12: WHSWBIW08S223 | D12: BD-08 | E12: 2 | F12: 500
B13: BR-3-2 | C13: WHSWPLCS042 | D13: 2746 | E13: 5 | F13: 2000
B14: BR-3-2 | C14: WHSWLTLEDS164 | D14: LED-1 | E14: 1 | F14: 1500
B15: BR-3-2 | C15: WHSWLTLEDS165 | D15: AL-1 | E15: 1 | F15: 500
B16: BR-3-2 | C16: WHSWLTLEDS167 | D16: PA-1 | E16: 1 | F16: 1500
B17: BR-3-2 | C17: WHSWCHALS162 | D17: ALC-1 | E17: 2 | F17: 1000
B18: BR-3-2 | C18: WHSWBDPS161 | D18: PVCBD-1 | E18: 1 | F18: 2500
B19: BR-3-2 | C19: WHSWBIW01S216 | D19: BD-01 | E19: 2 | F19: 500
B20: BR-4-1 | C20: WHSWPLCS021 | D20: 3223 | E20: 10 | F20: 1500
B21: BR-4-1 | C21: WHSWLTLEDS164 | D21: LED-1 | E21: 1 | F21: 1500
B22: BR-4-1 | C22: WHSWLTLEDS165 | D22: AL-1 | E22: 1 | F22: 500
B23: BR-4-1 | C23: WHSWLTLEDS167 | D23: PA-1 | E23: 1 | F23: 1500
B24: BR-4-1 | C24: WHSWCHALS162 | D24: ALC-1 | E24: 2 | F24: 1000
B25: BR-4-1 | C25: WHSWBDPS161 | D25: PVCBD-1 | E25: 2 | F25: 2500
B26: BR-4-1 | C26: WHSWSSBWBLWS171 | D26: SB | E26: 2 | F26: 1000
B27: BR-4-1 | C27: WHSWSRBWBLWS181 | D27: Shelf | E27: 1 | F27: 1000
B28: BR-4-1 | C28: WHSWBIW01S216 | D28: BD-01 | E28: 2 | F28: 500
B29: BR-4-2 | C29: WHSWPLCS055 | D29: 5656 | E29: 10 | F29: 2000
B30: BR-4-2 | C30: WHSWLTLEDS164 | D30: LED-1 | E30: 1 | F30: 1500
B31: BR-4-2 | C31: WHSWLTLEDS165 | D31: AL-1 | E31: 1 | F31: 500
B32: BR-4-2 | C32: WHSWLTLEDS167 | D32: PA-1 | E32: 1 | F32: 1500
B33: BR-4-2 | C33: WHSWCHALS162 | D33: ALC-1 | E33: 2 | F33: 1000
B34: BR-4-2 | C34: WHSWBDPS161 | D34: PVCBD-1 | E34: 2 | F34: 2500
B35: BR-4-2 | C35: WHSWSSBWBLWS171 | D35: SB | E35: 2 | F35: 1000
B36: BR-4-2 | C36: WHSWSRBWBLWS181 | D36: Shelf | E36: 1 | F36: 1000
B37: BR-4-2 | C37: WHSWBIW03S218 | D37: BD-03 | E37: 2 | F37: 500
B38: BR-5-1 | C38: WHSWPLCS106 | D38: 3889 | E38: 20 | F38: 1500
B39: BR-5-2 | C39: WHSWPLCS020 | D39: 3221 | E39: 20 | F39: 1500
B40: BR-6-1 | C40: WHSWPLCS025 | D40: 545 | E40: 20 | F40: 2000
...
